<?xml version="1.0" ?>
<!-- =================================================================================== -->
<!-- |    This document was autogenerated by xacro from hunter_se_gazebo_jiajie.xacro  | -->
<!-- |    EDITING THIS FILE BY HAND IS NOT RECOMMENDED                                 | -->
<!-- =================================================================================== -->
<!-- This URDF was automatically created by SolidWorks to URDF Exporter! Originally created by Stephen Brawner (brawner@gmail.com) 
     Commit Version: 1.6.0-1-g15f4949  Build Version: 1.6.7594.29634
     For more information, please see http://wiki.ros.org/sw_urdf_exporter -->
<robot name="hunter_se">
  <!-- Gazebo references -->
  <gazebo reference="base_link">
    <mu1 value="0.0"/>
    <mu2 value="0.0"/>
    <kp value="10000000.0"/>
    <kd value="1.0"/>
    <material>Gazebo/White</material>
  </gazebo>
  <gazebo reference="fr_left_link">
    <mu1 value="22.1"/>
    <mu2 value="1.0"/>
    <kp value="10000000.0"/>
    <kd value="1.0"/>
    <fdir1 value="1 0 0"/>
    <material>Gazebo/Black</material>
  </gazebo>
  <gazebo reference="fr_right_link">
    <mu1 value="22.1"/>
    <mu2 value="1.0"/>
    <kp value="10000000.0"/>
    <kd value="1.0"/>
    <fdir1 value="1 0 0"/>
    <material>Gazebo/Black</material>
  </gazebo>
  <gazebo reference="re_left_link">
    <mu1 value="22.1"/>
    <mu2 value="1.0"/>
    <kp value="10000000.0"/>
    <kd value="1.0"/>
    <fdir1 value="0 0 1"/>
    <material>Gazebo/Black</material>
  </gazebo>
  <gazebo reference="re_right_link">
    <mu1 value="22.1"/>
    <mu2 value="1.0"/>
    <kp value="10000000.0"/>
    <kd value="1.0"/>
    <fdir1 value="0 0 1"/>
    <material>Gazebo/Black</material>
  </gazebo>
  <gazebo>
    <plugin filename="libgazebo_ros_ackermann_drive.so" name="gazebo_ros_ackermann_drive">
      <ros>
        <remapping>cmd_vel:=cmd_vel</remapping>
        <remapping>odom:=odom</remapping>
        <remapping>distance:=distance</remapping>
      </ros>
      <update_rate>100.0</update_rate>
      <front_left_joint>fr_left_joint</front_left_joint>
      <front_right_joint>fr_right_joint</front_right_joint>
      <rear_left_joint>re_left_joint</rear_left_joint>
      <rear_right_joint>re_right_joint</rear_right_joint>
      <left_steering_joint>fr_steer_left_joint</left_steering_joint>
      <right_steering_joint>fr_steer_right_joint</right_steering_joint>
      <steering_wheel_joint>front_steer_joint</steering_wheel_joint>
      <max_steer>0.6458</max_steer>
      <max_steering_angle>7.85</max_steering_angle>
      <max_speed>20</max_speed>
      <left_steering_pid_gain>1500 0 1</left_steering_pid_gain>
      <left_steering_i_range>0 0</left_steering_i_range>
      <right_steering_pid_gain>1500 0 1</right_steering_pid_gain>
      <right_steering_i_range>0 0</right_steering_i_range>
      <linear_velocity_pid_gain>1000 0 1</linear_velocity_pid_gain>
      <linear_velocity_i_range>0 0</linear_velocity_i_range>
      <publish_odom>true</publish_odom>
      <publish_odom_tf>true</publish_odom_tf>
      <publish_wheel_tf>false</publish_wheel_tf>
      <publish_distance>true</publish_distance>
      <odometry_frame>odom</odometry_frame>
      <robot_base_frame>base_link</robot_base_frame>
    </plugin>
    <plugin filename="libgazebo_ros_joint_state_publisher.so" name="hunterse_joint_state">
      <ros>
        <remapping>~/out:=joint_states</remapping>
      </ros>
      <update_rate>30</update_rate>
      <joint_name>fr_left_joint</joint_name>
      <joint_name>fr_right_joint</joint_name>
      <joint_name>re_left_joint</joint_name>
      <joint_name>re_right_joint</joint_name>
      <joint_name>fr_steer_left_joint</joint_name>
      <joint_name>fr_steer_right_joint</joint_name>
      <joint_name>front_steer_joint</joint_name>
    </plugin>
  </gazebo>
  <link name="support">
    <visual>
      <geometry>
        <cylinder length="0.3465" radius="0.01"/>
      </geometry>
      <origin rpy="0 0 0" xyz="0 0 0.17325"/>
      <material name="red">
        <color rgba="0.8 0.2 0.0 0.8"/>
      </material>
    </visual>
    <collision>
      <geometry>
        <cylinder length="0.3465" radius="0.01"/>
      </geometry>
      <origin rpy="0 0 0" xyz="0 0 0.17325"/>
    </collision>
    <inertial>
      <mass value="0.02"/>
      <inertia ixx="3.8e-05" ixy="0" ixz="0" iyy="3.8e-05" iyz="0" izz="1.0000000000000002e-06"/>
    </inertial>
  </link>
  <joint name="support2base_link" type="fixed">
    <parent link="base_link"/>
    <child link="support"/>
    <origin rpy="0 0 0" xyz="0.34058 0 0"/>
  </joint>
  <link name="lidar">
    <visual>
      <geometry>
        <cylinder length="0.1" radius="0.05"/>
      </geometry>
      <origin rpy="0 0 0" xyz="0 0 0"/>
      <material name="black">
        <color rgba="0 0 0 1"/>
      </material>
    </visual>
    <collision>
      <geometry>
        <cylinder length="0.1" radius="0.05"/>
      </geometry>
      <origin rpy="0 0 0" xyz="0 0 0"/>
    </collision>
    <inertial>
      <mass value="0.2"/>
      <inertia ixx="0.0002916666666666667" ixy="0" ixz="0" iyy="0.0002916666666666667" iyz="0" izz="0.00025000000000000006"/>
    </inertial>
  </link>
  <joint name="lidar2support" type="fixed">
    <parent link="support"/>
    <child link="lidar"/>
    <origin rpy="0 0 0" xyz="0 0 0.3465"/>
  </joint>
  <!-- Gazebo configurations -->
  <gazebo reference="support">
    <material>Gazebo/White</material>
  </gazebo>
  <gazebo reference="lidar">
    <material>Gazebo/Black</material>
    <sensor name="laser_sensor" type="ray">
      <always_on>true</always_on>
      <visualize>true</visualize>
      <update_rate>5</update_rate>
      <pose>0 0 0 0 0 0</pose>
      <ray>
        <scan>
          <horizontal>
            <samples>360</samples>
            <resolution>1.000000</resolution>
            <min_angle>0.000000</min_angle>
            <max_angle>6.280000</max_angle>
          </horizontal>
        </scan>
        <range>
          <min>0.120000</min>
          <max>3.5</max>
          <resolution>0.015000</resolution>
        </range>
        <noise>
          <type>gaussian</type>
          <mean>0.0</mean>
          <stddev>0.01</stddev>
        </noise>
      </ray>
      <plugin filename="libgazebo_ros_ray_sensor.so" name="laserscan">
        <ros>
          <remapping>~/out:=scan</remapping>
        </ros>
        <output_type>sensor_msgs/LaserScan</output_type>
        <frame_name>lidar</frame_name>
      </plugin>
    </sensor>
  </gazebo>
  <link name="base_link">
    <inertial>
      <origin rpy="0 0 0" xyz="0.0374140021041951 -0.000373005187591258 -0.0771282894414029"/>
      <mass value="10"/>
      <inertia ixx="0.123215829336501" ixy="-2.51201031615063E-06" ixz="0.00480100638469038" iyy="0.219144715482931" iyz="-1.0329581476775E-05" izz="0.313606030126045"/>
    </inertial>
    <visual>
      <origin rpy="0 0 0" xyz="0 0 0"/>
      <geometry>
        <mesh filename="file:///home/jay/hunter_sim_ws/install/hunter_se_description/share/hunter_se_description/meshes/base_link.STL"/>
      </geometry>
      <material name="">
        <color rgba="0.752941176470588 0.752941176470588 0.752941176470588 1"/>
      </material>
    </visual>
    <collision>
      <origin rpy="0 0 0" xyz="0 0 0"/>
      <geometry>
        <mesh filename="file:///home/jay/hunter_sim_ws/install/hunter_se_description/share/hunter_se_description/meshes/base_link.STL"/>
      </geometry>
    </collision>
  </link>
  <link name="fr_steer_left_link">
    <inertial>
      <origin rpy="0 0 0" xyz="-0.0002776492198312 0.0163539773588368 4.97346169803237E-09"/>
      <mass value="0.5"/>
      <inertia ixx="0.0222" ixy="0.0" ixz="0.0" iyy="0.0222" iyz="0.0" izz="0.0378075"/>
    </inertial>
    <visual>
      <origin rpy="0 0 0" xyz="0 0 0"/>
      <geometry>
        <box size="0.001 0.001 0.001"/>
      </geometry>
      <material name="">
        <color rgba="0.223529411764706 0.223529411764706 0.223529411764706 1"/>
      </material>
    </visual>
    <collision>
      <origin rpy="0 0 0" xyz="0 0 0"/>
      <geometry>
        <box size="0.001 0.001 0.001"/>
      </geometry>
    </collision>
  </link>
  <joint name="fr_steer_left_joint" type="continuous">
    <origin rpy="0 0 0" xyz="0.34058 0.24619 -0.1535"/>
    <parent link="base_link"/>
    <child link="fr_steer_left_link"/>
    <axis xyz="0 0 1"/>
    <limit effort="10" lower="-0.69" upper="0.69" velocity="0.69"/>
  </joint>
  <link name="fr_left_link">
    <inertial>
      <origin rpy="0 0 0" xyz="-3.5837499634539E-10 4.97346158701006E-09 -0.016356334080185"/>
      <mass value="1"/>
      <inertia ixx="0.0222" ixy="0.0" ixz="0.0" iyy="0.0222" iyz="0.0" izz="0.0378075"/>
    </inertial>
    <visual>
      <origin rpy="0 0 0" xyz="0 0 0"/>
      <geometry>
        <mesh filename="file:///home/jay/hunter_sim_ws/install/hunter_se_description/share/hunter_se_description/meshes/fr_left_link.STL"/>
      </geometry>
      <material name="">
        <color rgba="0.223529411764706 0.223529411764706 0.223529411764706 1"/>
      </material>
    </visual>
    <collision>
      <origin rpy="0 0 0" xyz="0 0 0"/>
      <geometry>
        <!-- <mesh
          filename="file://$(find hunter_se_description)/meshes/fr_left_link.STL" /> -->
        <cylinder length="0.045" radius="0.13"/>
      </geometry>
    </collision>
  </link>
  <joint name="fr_left_joint" type="continuous">
    <origin rpy="1.5708 0 0.016976" xyz="0 0 0"/>
    <parent link="fr_steer_left_link"/>
    <child link="fr_left_link"/>
    <axis xyz="0 0 -1"/>
    <limit effort="10" velocity="100"/>
  </joint>
  <link name="fr_steer_right_link">
    <inertial>
      <origin rpy="0 0 0" xyz="0.000274981985673328 -0.0163540222836661 -3.24802407192237E-11"/>
      <mass value="1"/>
      <inertia ixx="0.0222" ixy="0.0" ixz="0.0" iyy="0.0222" iyz="0.0" izz="0.0378075"/>
    </inertial>
    <visual>
      <origin rpy="0 0 0" xyz="0 0 0"/>
      <geometry>
        <box size="0.001 0.001 0.001"/>
      </geometry>
      <material name="">
        <color rgba="1 1 1 1"/>
      </material>
    </visual>
    <collision>
      <origin rpy="0 0 0" xyz="0 0 0"/>
      <geometry>
        <box size="0.001 0.001 0.001"/>
      </geometry>
    </collision>
  </link>
  <joint name="fr_steer_right_joint" type="continuous">
    <origin rpy="0 0 0" xyz="0.34219 -0.24619 -0.1535"/>
    <parent link="base_link"/>
    <child link="fr_steer_right_link"/>
    <axis xyz="0 0 1"/>
    <limit effort="10" lower="-0.69" upper="0.69" velocity="0.69"/>
  </joint>
  <link name="fr_right_link">
    <inertial>
      <origin rpy="0 0 0" xyz="0.00027498198567355 3.24801296969213E-11 -0.0163540222836661"/>
      <mass value="1"/>
      <inertia ixx="0.0222" ixy="0.0" ixz="0.0" iyy="0.0222" iyz="0.0" izz="0.0378075"/>
    </inertial>
    <visual>
      <origin rpy="0 0 0" xyz="0 0 0"/>
      <geometry>
        <mesh filename="file:///home/jay/hunter_sim_ws/install/hunter_se_description/share/hunter_se_description/meshes/fr_right_link.STL"/>
      </geometry>
      <material name="">
        <color rgba="0.223529411764706 0.223529411764706 0.223529411764706 1"/>
      </material>
    </visual>
    <collision>
      <origin rpy="0 0 0" xyz="0 0 0"/>
      <geometry>
        <!-- <mesh
          filename="file://$(find hunter_se_description)/meshes/fr_right_link.STL" /> -->
        <cylinder length="0.045" radius="0.13"/>
      </geometry>
    </collision>
  </link>
  <joint name="fr_right_joint" type="continuous">
    <origin rpy="-1.5708 0 0" xyz="0 0 0"/>
    <parent link="fr_steer_right_link"/>
    <child link="fr_right_link"/>
    <axis xyz="0 0 1"/>
    <limit effort="10" velocity="100"/>
  </joint>
  <link name="re_left_link">
    <inertial>
      <origin rpy="0 0 0" xyz="1.245E-09 1.7252E-06 -0.010284"/>
      <mass value="1"/>
      <inertia ixx="0.0222" ixy="0.0" ixz="0.0" iyy="0.0222" iyz="0.0" izz="0.0378075"/>
    </inertial>
    <visual>
      <origin rpy="0 0 0" xyz="0 0 0"/>
      <geometry>
        <mesh filename="file:///home/jay/hunter_sim_ws/install/hunter_se_description/share/hunter_se_description/meshes/re_left_link.STL"/>
      </geometry>
      <material name="">
        <color rgba="0.37647 0.37647 0.37647 1"/>
      </material>
    </visual>
    <collision>
      <origin rpy="0 0 0" xyz="0 0 0"/>
      <geometry>
        <!-- <mesh
          filename="file://$(find hunter_se_description)/meshes/re_left_link.STL" /> -->
        <cylinder length="0.045" radius="0.13"/>
      </geometry>
    </collision>
  </link>
  <joint name="re_left_joint" type="continuous">
    <origin rpy="1.5708 0 0" xyz="-0.2078 0.252 -0.158"/>
    <parent link="base_link"/>
    <child link="re_left_link"/>
    <axis xyz="0 0 -1"/>
    <limit effort="10" velocity="100"/>
  </joint>
  <link name="re_right_link">
    <inertial>
      <origin rpy="0 0 0" xyz="0 0 0"/>
      <mass value="1"/>
      <inertia ixx="0.0222" ixy="0.0" ixz="0.0" iyy="0.0222" iyz="0.0" izz="0.0378075"/>
    </inertial>
    <visual>
      <origin rpy="0 0 0" xyz="0 0 0"/>
      <geometry>
        <mesh filename="file:///home/jay/hunter_sim_ws/install/hunter_se_description/share/hunter_se_description/meshes/re_right_link.STL"/>
      </geometry>
      <material name="">
        <color rgba="1 1 1 1"/>
      </material>
    </visual>
    <collision>
      <origin rpy="0 0 0" xyz="0 0 0"/>
      <geometry>
        <!-- <mesh
          filename="file://$(find hunter_se_description)/meshes/re_right_link.STL" /> -->
        <cylinder length="0.045" radius="0.13"/>
      </geometry>
    </collision>
  </link>
  <joint name="re_right_joint" type="continuous">
    <origin rpy="-1.5708 0 0" xyz="-0.2078 -0.252 -0.158"/>
    <parent link="base_link"/>
    <child link="re_right_link"/>
    <axis xyz="0 0 1"/>
    <limit effort="10" velocity="100"/>
  </joint>
  <link name="front_steer_link">
    <inertial>
      <origin rpy="0 0 0" xyz="0.049836 8.1046E-15 0.017912"/>
      <mass value="0.049179"/>
      <inertia ixx="1.6846E-07" ixy="7.6396E-23" ixz="-1.0974E-08" iyy="7.549E-07" iyz="-1.8957E-22" izz="7.334E-07"/>
    </inertial>
    <visual>
      <origin rpy="0 0 0" xyz="0 0 0"/>
      <geometry>
        <cylinder length="0.001" radius="0.005"/>
      </geometry>
      <material name="">
        <color rgba="0.79216 0.81961 0.93333 1"/>
      </material>
    </visual>
    <collision>
      <origin rpy="0 0 0" xyz="0 0 0"/>
      <geometry>
        <cylinder length="0.001" radius="0.005"/>
      </geometry>
    </collision>
  </link>
  <joint name="front_steer_joint" type="continuous">
    <origin rpy="0 0 0" xyz="0.40792 -1.1431E-05 -0.085581"/>
    <parent link="base_link"/>
    <child link="front_steer_link"/>
    <axis xyz="0 0 1"/>
    <limit effort="10" lower="-0.72" upper="0.72" velocity="100"/>
  </joint>
  <link name="rear_wheel_link">
    <inertial>
      <origin rpy="0 0 0" xyz="-0.02 0.0031269 -0.12735"/>
      <mass value="0.049179"/>
      <inertia ixx="1.1821E-06" ixy="9.6965E-13" ixz="-3.1553E-12" iyy="9.5276E-07" iyz="1.2428E-08" izz="1.0913E-06"/>
    </inertial>
    <visual>
      <origin rpy="0 0 0" xyz="0 0 0"/>
      <geometry>
        <cylinder length="0.001" radius="0.005"/>
      </geometry>
      <material name="">
        <color rgba="1 1 1 1"/>
      </material>
    </visual>
    <collision>
      <origin rpy="0 0 0" xyz="0 0 0"/>
      <geometry>
        <cylinder length="0.001" radius="0.005"/>
      </geometry>
    </collision>
  </link>
  <joint name="rear_wheel_joint" type="fixed">
    <origin rpy="0.0032313 0 0" xyz="-0.30408 -1.1431E-05 -0.085581"/>
    <parent link="base_link"/>
    <child link="rear_wheel_link"/>
    <axis xyz="0 0 1"/>
  </joint>
  <transmission name="fr_steer_left_transmission" type="SimpleTransmission">
    <type>transmission_interface/SimpleTransmission</type>
    <joint name="fr_steer_left_joint">
      <hardwareInterface>EffortJointInterface</hardwareInterface>
    </joint>
    <actuator name="fr_steer_left_motor">
      <hardwareInterface>EffortJointInterface</hardwareInterface>
      <mechanicalReduction>1</mechanicalReduction>
    </actuator>
  </transmission>
  <transmission name="fr_steer_right_transmission" type="SimpleTransmission">
    <type>transmission_interface/SimpleTransmission</type>
    <joint name="fr_steer_right_joint">
      <hardwareInterface>EffortJointInterface</hardwareInterface>
    </joint>
    <actuator name="fr_steer_right_motor">
      <hardwareInterface>EffortJointInterface</hardwareInterface>
      <mechanicalReduction>1</mechanicalReduction>
    </actuator>
  </transmission>
  <transmission name="front_steer_transmission" type="SimpleTransmission">
    <type>transmission_interface/SimpleTransmission</type>
    <joint name="front_steer_joint">
      <hardwareInterface>EffortJointInterface</hardwareInterface>
    </joint>
    <actuator name="front_steer_motor">
      <hardwareInterface>EffortJointInterface</hardwareInterface>
      <mechanicalReduction>1</mechanicalReduction>
    </actuator>
  </transmission>
  <transmission name="fr_left_transmission" type="SimpleTransmission">
    <type>transmission_interface/SimpleTransmission</type>
    <joint name="fr_left_joint">
      <hardwareInterface>EffortJointInterface</hardwareInterface>
    </joint>
    <actuator name="fr_left_motor">
      <hardwareInterface>EffortJointInterface</hardwareInterface>
      <mechanicalReduction>1</mechanicalReduction>
    </actuator>
  </transmission>
  <transmission name="fr_right_transmission" type="SimpleTransmission">
    <type>transmission_interface/SimpleTransmission</type>
    <joint name="fr_right_joint">
      <hardwareInterface>EffortJointInterface</hardwareInterface>
    </joint>
    <actuator name="fr_right_motor">
      <hardwareInterface>EffortJointInterface</hardwareInterface>
      <mechanicalReduction>1</mechanicalReduction>
    </actuator>
  </transmission>
  <transmission name="re_left_transmission" type="SimpleTransmission">
    <type>transmission_interface/SimpleTransmission</type>
    <joint name="re_left_joint">
      <hardwareInterface>EffortJointInterface</hardwareInterface>
    </joint>
    <actuator name="re_left_motor">
      <hardwareInterface>EffortJointInterface</hardwareInterface>
      <mechanicalReduction>1</mechanicalReduction>
    </actuator>
  </transmission>
  <transmission name="re_right_transmission" type="SimpleTransmission">
    <type>transmission_interface/SimpleTransmission</type>
    <joint name="re_right_joint">
      <hardwareInterface>EffortJointInterface</hardwareInterface>
    </joint>
    <actuator name="re_right_motor">
      <hardwareInterface>EffortJointInterface</hardwareInterface>
      <mechanicalReduction>1</mechanicalReduction>
    </actuator>
  </transmission>
</robot>
